[2023-12-02 14:00:32 +0000] [80528] [INFO] Starting gunicorn 21.2.0
[2023-12-02 14:00:32 +0000] [80528] [INFO] Listening at: http://0.0.0.0:8000 (80528)
[2023-12-02 14:00:32 +0000] [80528] [INFO] Using worker: sync
[2023-12-02 14:00:32 +0000] [80529] [INFO] Booting worker with pid: 80529
[2023-12-02 14:00:32 +0000] [80529] [ERROR] Exception in worker process
Traceback (most recent call last):
  File "/root/myenv/lib/python3.11/site-packages/gunicorn/arbiter.py", line 609, in spawn_worker
    worker.init_process()
  File "/root/myenv/lib/python3.11/site-packages/gunicorn/workers/base.py", line 134, in init_process
    self.load_wsgi()
  File "/root/myenv/lib/python3.11/site-packages/gunicorn/workers/base.py", line 146, in load_wsgi
    self.wsgi = self.app.wsgi()
                ^^^^^^^^^^^^^^^
  File "/root/myenv/lib/python3.11/site-packages/gunicorn/app/base.py", line 67, in wsgi
    self.callable = self.load()
                    ^^^^^^^^^^^
  File "/root/myenv/lib/python3.11/site-packages/gunicorn/app/wsgiapp.py", line 58, in load
    return self.load_wsgiapp()
           ^^^^^^^^^^^^^^^^^^^
  File "/root/myenv/lib/python3.11/site-packages/gunicorn/app/wsgiapp.py", line 48, in load_wsgiapp
    return util.import_app(self.app_uri)
           ^^^^^^^^^^^^^^^^^^^^^^^^^^^^^
  File "/root/myenv/lib/python3.11/site-packages/gunicorn/util.py", line 371, in import_app
    mod = importlib.import_module(module)
          ^^^^^^^^^^^^^^^^^^^^^^^^^^^^^^^
  File "/usr/lib/python3.11/importlib/__init__.py", line 126, in import_module
    return _bootstrap._gcd_import(name[level:], package, level)
           ^^^^^^^^^^^^^^^^^^^^^^^^^^^^^^^^^^^^^^^^^^^^^^^^^^^^
  File "<frozen importlib._bootstrap>", line 1204, in _gcd_import
  File "<frozen importlib._bootstrap>", line 1176, in _find_and_load
  File "<frozen importlib._bootstrap>", line 1147, in _find_and_load_unlocked
  File "<frozen importlib._bootstrap>", line 690, in _load_unlocked
  File "<frozen importlib._bootstrap_external>", line 940, in exec_module
  File "<frozen importlib._bootstrap>", line 241, in _call_with_frames_removed
  File "/root/malffler/bob/wsgi.py", line 16, in <module>
    application = get_wsgi_application()
                  ^^^^^^^^^^^^^^^^^^^^^^
  File "/root/myenv/lib/python3.11/site-packages/django/core/wsgi.py", line 12, in get_wsgi_application
    django.setup(set_prefix=False)
  File "/root/myenv/lib/python3.11/site-packages/django/__init__.py", line 19, in setup
    configure_logging(settings.LOGGING_CONFIG, settings.LOGGING)
                      ^^^^^^^^^^^^^^^^^^^^^^^
  File "/root/myenv/lib/python3.11/site-packages/django/conf/__init__.py", line 102, in __getattr__
    self._setup(name)
  File "/root/myenv/lib/python3.11/site-packages/django/conf/__init__.py", line 89, in _setup
    self._wrapped = Settings(settings_module)
                    ^^^^^^^^^^^^^^^^^^^^^^^^^
  File "/root/myenv/lib/python3.11/site-packages/django/conf/__init__.py", line 217, in __init__
    mod = importlib.import_module(self.SETTINGS_MODULE)
          ^^^^^^^^^^^^^^^^^^^^^^^^^^^^^^^^^^^^^^^^^^^^^
  File "/usr/lib/python3.11/importlib/__init__.py", line 126, in import_module
    return _bootstrap._gcd_import(name[level:], package, level)
           ^^^^^^^^^^^^^^^^^^^^^^^^^^^^^^^^^^^^^^^^^^^^^^^^^^^^
  File "<frozen importlib._bootstrap>", line 1204, in _gcd_import
  File "<frozen importlib._bootstrap>", line 1176, in _find_and_load
  File "<frozen importlib._bootstrap>", line 1147, in _find_and_load_unlocked
  File "<frozen importlib._bootstrap>", line 690, in _load_unlocked
  File "<frozen importlib._bootstrap_external>", line 936, in exec_module
  File "<frozen importlib._bootstrap_external>", line 1074, in get_code
  File "<frozen importlib._bootstrap_external>", line 1004, in source_to_code
  File "<frozen importlib._bootstrap>", line 241, in _call_with_frames_removed
  File "/root/malffler/bob/settings.py", line 32
    aU(`R*`R+`R,aR,aR,aR,INSTALLED_APPS = [
       ^
SyntaxError: invalid syntax
[2023-12-02 14:00:32 +0000] [80529] [INFO] Worker exiting (pid: 80529)
[2023-12-02 14:00:32 +0000] [80528] [ERROR] Worker (pid:80529) exited with code 3
[2023-12-02 14:00:32 +0000] [80528] [ERROR] Shutting down: Master
[2023-12-02 14:00:32 +0000] [80528] [ERROR] Reason: Worker failed to boot.
